Traceback (most recent call last):
  File "C:\Users\masonl\AppData\Local\Continuum\anaconda3\envs\jbook\lib\site-packages\jupyter_cache\executors\utils.py", line 56, in single_nb_execution
    record_timing=False,
  File "C:\Users\masonl\AppData\Local\Continuum\anaconda3\envs\jbook\lib\site-packages\nbclient\client.py", line 1204, in execute
    return NotebookClient(nb=nb, resources=resources, km=km, **kwargs).execute()
  File "C:\Users\masonl\AppData\Local\Continuum\anaconda3\envs\jbook\lib\site-packages\nbclient\util.py", line 84, in wrapped
    return just_run(coro(*args, **kwargs))
  File "C:\Users\masonl\AppData\Local\Continuum\anaconda3\envs\jbook\lib\site-packages\nbclient\util.py", line 62, in just_run
    return loop.run_until_complete(coro)
  File "C:\Users\masonl\AppData\Local\Continuum\anaconda3\envs\jbook\lib\asyncio\base_events.py", line 587, in run_until_complete
    return future.result()
  File "C:\Users\masonl\AppData\Local\Continuum\anaconda3\envs\jbook\lib\site-packages\nbclient\client.py", line 664, in async_execute
    cell, index, execution_count=self.code_cells_executed + 1
  File "C:\Users\masonl\AppData\Local\Continuum\anaconda3\envs\jbook\lib\site-packages\nbclient\client.py", line 965, in async_execute_cell
    await self._check_raise_for_error(cell, cell_index, exec_reply)
  File "C:\Users\masonl\AppData\Local\Continuum\anaconda3\envs\jbook\lib\site-packages\nbclient\client.py", line 862, in _check_raise_for_error
    raise CellExecutionError.from_cell_and_msg(cell, exec_reply_content)
nbclient.exceptions.CellExecutionError: An error occurred while executing the following cell:
------------------
%matplotlib inline
from pylab import *
import numpy as np
import matplotlib.tri as Tri
import matplotlib.pyplot as plt
import netCDF4
import datetime as dt
import pandas as pd
from io import StringIO


%config InlineBackend.figure_format = 'svg'
plt.rcParams['mathtext.fontset'] = 'cm'

import warnings
warnings.filterwarnings('ignore')
------------------

[1;31m---------------------------------------------------------------------------[0m
[1;31mModuleNotFoundError[0m                       Traceback (most recent call last)
[1;32m~\AppData\Local\Temp\1\ipykernel_2272\1443253751.py[0m in [0;36m<module>[1;34m[0m
[0;32m      6[0m [1;32mimport[0m [0mnetCDF4[0m[1;33m[0m[1;33m[0m[0m
[0;32m      7[0m [1;32mimport[0m [0mdatetime[0m [1;32mas[0m [0mdt[0m[1;33m[0m[1;33m[0m[0m
[1;32m----> 8[1;33m [1;32mimport[0m [0mpandas[0m [1;32mas[0m [0mpd[0m[1;33m[0m[1;33m[0m[0m
[0m[0;32m      9[0m [1;32mfrom[0m [0mio[0m [1;32mimport[0m [0mStringIO[0m[1;33m[0m[1;33m[0m[0m
[0;32m     10[0m [1;33m[0m[0m

[1;31mModuleNotFoundError[0m: No module named 'pandas'
ModuleNotFoundError: No module named 'pandas'

