Traceback (most recent call last):
  File "C:\Users\masonl\AppData\Local\anaconda3\envs\jbookr\Lib\site-packages\jupyter_cache\executors\utils.py", line 58, in single_nb_execution
    executenb(
  File "C:\Users\masonl\AppData\Local\anaconda3\envs\jbookr\Lib\site-packages\nbclient\client.py", line 1204, in execute
    return NotebookClient(nb=nb, resources=resources, km=km, **kwargs).execute()
           ^^^^^^^^^^^^^^^^^^^^^^^^^^^^^^^^^^^^^^^^^^^^^^^^^^^^^^^^^^^^^^^^^^^^^
  File "C:\Users\masonl\AppData\Local\anaconda3\envs\jbookr\Lib\site-packages\nbclient\util.py", line 84, in wrapped
    return just_run(coro(*args, **kwargs))
           ^^^^^^^^^^^^^^^^^^^^^^^^^^^^^^^
  File "C:\Users\masonl\AppData\Local\anaconda3\envs\jbookr\Lib\site-packages\nbclient\util.py", line 62, in just_run
    return loop.run_until_complete(coro)
           ^^^^^^^^^^^^^^^^^^^^^^^^^^^^^
  File "C:\Users\masonl\AppData\Local\anaconda3\envs\jbookr\Lib\asyncio\base_events.py", line 653, in run_until_complete
    return future.result()
           ^^^^^^^^^^^^^^^
  File "C:\Users\masonl\AppData\Local\anaconda3\envs\jbookr\Lib\site-packages\nbclient\client.py", line 663, in async_execute
    await self.async_execute_cell(
  File "C:\Users\masonl\AppData\Local\anaconda3\envs\jbookr\Lib\site-packages\nbclient\client.py", line 965, in async_execute_cell
    await self._check_raise_for_error(cell, cell_index, exec_reply)
  File "C:\Users\masonl\AppData\Local\anaconda3\envs\jbookr\Lib\site-packages\nbclient\client.py", line 862, in _check_raise_for_error
    raise CellExecutionError.from_cell_and_msg(cell, exec_reply_content)
nbclient.exceptions.CellExecutionError: An error occurred while executing the following cell:
------------------
for i in range(len(obs)):
    # Find depth in meters of center of sigma layer
    depths=nc.variables['siglay'][:,obs['NODE-ID'][i]] * nc.variables['h'][obs['NODE-ID'][i]]
    z[:,i] = nc['temp'][0,:,obs['NODE-ID'][i]]
------------------

[1;31m---------------------------------------------------------------------------[0m
[1;31mRuntimeError[0m                              Traceback (most recent call last)
Cell [1;32mIn[19], line 4[0m
[0;32m      1[0m [38;5;28;01mfor[39;00m i [38;5;129;01min[39;00m [38;5;28mrange[39m([38;5;28mlen[39m(obs)):
[0;32m      2[0m     [38;5;66;03m# Find depth in meters of center of sigma layer[39;00m
[0;32m      3[0m     depths[38;5;241m=[39mnc[38;5;241m.[39mvariables[[38;5;124m'[39m[38;5;124msiglay[39m[38;5;124m'[39m][:,obs[[38;5;124m'[39m[38;5;124mNODE-ID[39m[38;5;124m'[39m][i]] [38;5;241m*[39m nc[38;5;241m.[39mvariables[[38;5;124m'[39m[38;5;124mh[39m[38;5;124m'[39m][obs[[38;5;124m'[39m[38;5;124mNODE-ID[39m[38;5;124m'[39m][i]]
[1;32m----> 4[0m     z[:,i] [38;5;241m=[39m [43mnc[49m[43m[[49m[38;5;124;43m'[39;49m[38;5;124;43mtemp[39;49m[38;5;124;43m'[39;49m[43m][49m[43m[[49m[38;5;241;43m0[39;49m[43m,[49m[43m:[49m[43m,[49m[43mobs[49m[43m[[49m[38;5;124;43m'[39;49m[38;5;124;43mNODE-ID[39;49m[38;5;124;43m'[39;49m[43m][49m[43m[[49m[43mi[49m[43m][49m[43m][49m

File [1;32msrc\netCDF4\_netCDF4.pyx:4940[0m, in [0;36mnetCDF4._netCDF4.Variable.__getitem__[1;34m()[0m

File [1;32msrc\netCDF4\_netCDF4.pyx:5898[0m, in [0;36mnetCDF4._netCDF4.Variable._get[1;34m()[0m

File [1;32msrc\netCDF4\_netCDF4.pyx:2014[0m, in [0;36mnetCDF4._netCDF4._ensure_nc_success[1;34m()[0m

[1;31mRuntimeError[0m: NetCDF: Authorization failure
RuntimeError: NetCDF: Authorization failure

